Workbook

Sheet 總表
A1: 地區 | B1: 村莊 | C1: 名稱 | D1: 貢獻 | E1: 用途 | F1: 用途等級 | G1: 格數 | H1: CP值
A2: 巴雷諾斯自治領 | B2: 貝爾利亞村莊 | C2: 貝爾利亞1號3號室 | D2: 1 | E2: 倉庫 | F2: 2 | G2: 5 | H2: =ROUND(IF(OR(總表!$G2="",總表!$D2=""),"0",(總表!$G2/總表!$D2)),2) -> 5
A3: 巴雷諾斯自治領 | B3: 貝爾利亞村莊 | C3: 巴雷諾斯1-2號,巴特利農場 | D3: 1 | E3: 倉庫 | F3: 2 | G3: 5 | H3: =ROUND(IF(OR(總表!$G3="",總表!$D3=""),"0",(總表!$G3/總表!$D3)),2) -> 5
A4: 巴雷諾斯自治領 | B4: 貝爾利亞村莊 | C4: 巴雷諾斯4-2號,戴爾魯茲農場 | D4: 1 | E4: 倉庫 | F4: 2 | G4: 5 | H4: =ROUND(IF(OR(總表!$G4="",總表!$D4=""),"0",(總表!$G4/總表!$D4)),2) -> 5
A5: 巴雷諾斯自治領 | B5: 貝爾利亞村莊 | C5: 巴雷諾斯3-2號,洛基亞農場 | D5: 1 | E5: 倉庫 | F5: 2 | G5: 5 | H5: =ROUND(IF(OR(總表!$G5="",總表!$D5=""),"0",(總表!$G5/總表!$D5)),2) -> 5
A6: 巴雷諾斯自治領 | B6: 奧爾比亞村莊 | C6: 奧爾比亞2-4號 | D6: 1 | E6: 倉庫 | F6: 2 | G6: 5 | H6: =ROUND(IF(OR(總表!$G6="",總表!$D6=""),"0",(總表!$G6/總表!$D6)),2) -> 5
A7: 巴雷諾斯自治領 | B7: 奧爾比亞村莊 | C7: 奧爾比亞5-2號 | D7: 1 | E7: 倉庫 | F7: 2 | G7: 5 | H7: =ROUND(IF(OR(總表!$G7="",總表!$D7=""),"0",(總表!$G7/總表!$D7)),2) -> 5
A8: 巴雷諾斯自治領 | B8: 奧爾比亞村莊 | C8: 奧爾比亞4-1號 | D8: 1 | E8: 倉庫 | F8: 2 | G8: 5 | H8: =ROUND(IF(OR(總表!$G8="",總表!$D8=""),"0",(總表!$G8/總表!$D8)),2) -> 5
A9: 巴雷諾斯自治領 | B9: 奧爾比亞村莊 | C9: 奧爾比亞7-2號2樓 | D9: 1 | E9: 倉庫 | F9: 2 | G9: 5 | H9: =ROUND(IF(OR(總表!$G9="",總表!$D9=""),"0",(總表!$G9/總表!$D9)),2) -> 5
A10: 巴雷諾斯自治領 | B10: 奧爾比亞村莊 | C10: 奧爾比亞7-3號 | D10: 1 | E10: 倉庫 | F10: 2 | G10: 5 | H10: =ROUND(IF(OR(總表!$G10="",總表!$D10=""),"0",(總表!$G10/總表!$D10)),2) -> 5
A11: 巴雷諾斯自治領 | B11: 貝爾利亞村莊 | C11: 巴雷諾斯6-2號,托斯卡尼農場 | D11: 3 | E11: 倉庫 | F11: 4 | G11: 12 | H11: =ROUND(IF(OR(總表!$G11="",總表!$D11=""),"0",(總表!$G11/總表!$D11)),2) -> 4
A12: 巴雷諾斯自治領 | B12: 伊利亞島 | C12: 伊利亞島2-2號 | D12: 2 | E12: 倉庫 | F12: 3 | G12: 8 | H12: =ROUND(IF(OR(總表!$G12="",總表!$D12=""),"0",(總表!$G12/總表!$D12)),2) -> 4
A13: 巴雷諾斯自治領 | B13: 奧爾比亞村莊 | C13: 奧爾比亞2-5號1樓 | D13: 2 | E13: 倉庫 | F13: 3 | G13: 8 | H13: =ROUND(IF(OR(總表!$G13="",總表!$D13=""),"0",(總表!$G13/總表!$D13)),2) -> 4
... A18: 巴雷諾斯自治領 | B18: 貝爾利亞村莊 | C18: 貝爾利亞3-1號 | D18: 1 | E18: 倉庫 | F18: 1 | G18: 3 | H18: =ROUND(IF(OR(總表!$G18="",總表!$D18=""),"0",(總表!$G18/總表!$D18)),2) -> 3
A19: 巴雷諾斯自治領 | B19: 貝爾利亞村莊 | C19: 貝爾利亞3-1號 | D19: 1 | E19: 殘月家具工坊 | F19: 3 | H19: =ROUND(IF(OR(總表!$G19="",總表!$D19=""),"0",(總表!$G19/總表!$D19)),2) -> 0
A20: 巴雷諾斯自治領 | B20: 貝爾利亞村莊 | C20: 貝爾利亞2-1號 | D20: 1 | E20: 倉庫 | F20: 1 | G20: 3 | H20: =ROUND(IF(OR(總表!$G20="",總表!$D20=""),"0",(總表!$G20/總表!$D20)),2) -> 3
A21: 巴雷諾斯自治領 | B21: 貝爾利亞村莊 | C21: 貝爾利亞1號1號室 | D21: 1 | E21: 倉庫 | F21: 1 | G21: 3 | H21: =ROUND(IF(OR(總表!$G21="",總表!$D21=""),"0",(總表!$G21/總表!$D21)),2) -> 3
A22: 巴雷諾斯自治領 | B22: 貝爾利亞村莊 | C22: 貝爾利亞1號2號室 | D22: 1 | E22: 倉庫 | F22: 1 | G22: 3 | H22: =ROUND(IF(OR(總表!$G22="",總表!$D22=""),"0",(總表!$G22/總表!$D22)),2) -> 3
A23: 巴雷諾斯自治領 | B23: 貝爾利亞村莊 | C23: 巴雷諾斯2-1號,品特農場 | D23: 1 | E23: 倉庫 | F23: 1 | G23: 3 | H23: =ROUND(IF(OR(總表!$G23="",總表!$D23=""),"0",(總表!$G23/總表!$D23)),2) -> 3
A24: 巴雷諾斯自治領 | B24: 伊利亞島 | C24: 雷瑪島1號 | D24: 1 | E24: 倉庫 | F24: 1 | G24: 3 | H24: =ROUND(IF(OR(總表!$G24="",總表!$D24=""),"0",(總表!$G24/總表!$D24)),2) -> 3
A25: 巴雷諾斯自治領 | B25: 伊利亞島 | C25: 伊利亞島1-1號 | D25: 1 | E25: 倉庫 | F25: 1 | G25: 3 | H25: =ROUND(IF(OR(總表!$G25="",總表!$D25=""),"0",(總表!$G25/總表!$D25)),2) -> 3
A26: 巴雷諾斯自治領 | B26: 伊利亞島 | C26: 伊利亞島1-1號 | D26: 1 | E26: 殘月家具工坊 | F26: 3 | H26: =ROUND(IF(OR(總表!$G26="",總表!$D26=""),"0",(總表!$G26/總表!$D26)),2) -> 0
A27: 巴雷諾斯自治領 | B27: 伊利亞島 | C27: 伊利亞島1-2號 | D27: 1 | E27: 倉庫 | F27: 1 | G27: 3 | H27: =ROUND(IF(OR(總表!$G27="",總表!$D27=""),"0",(總表!$G27/總表!$D27)),2) -> 3
A28: 巴雷諾斯自治領 | B28: 伊利亞島 | C28: 伊利亞島4-2號 | D28: 1 | E28: 倉庫 | F28: 1 | G28: 3 | H28: =ROUND(IF(OR(總表!$G28="",總表!$D28=""),"0",(總表!$G28/總表!$D28)),2) -> 3
A29: 巴雷諾斯自治領 | B29: 伊利亞島 | C29: 伊利亞島6-1號 | D29: 1 | E29: 倉庫 | F29: 1 | G29: 3 | H29: =ROUND(IF(OR(總表!$G29="",總表!$D29=""),"0",(總表!$G29/總表!$D29)),2) -> 3
A30: 巴雷諾斯自治領 | B30: 奧爾比亞村莊 | C30: 奧爾比亞1-1號 | D30: 1 | E30: 倉庫 | F30: 1 | G30: 3 | H30: =ROUND(IF(OR(總表!$G30="",總表!$D30=""),"0",(總表!$G30/總表!$D30)),2) -> 3
A31: 巴雷諾斯自治領 | B31: 奧爾比亞村莊 | C31: 奧爾比亞1-2號 | D31: 1 | E31: 倉庫 | F31: 1 | G31: 3 | H31: =ROUND(IF(OR(總表!$G31="",總表!$D31=""),"0",(總表!$G31/總表!$D31)),2) -> 3
A32: 巴雷諾斯自治領 | B32: 奧爾比亞村莊 | C32: 奧爾比亞2-2號 | D32: 1 | E32: 倉庫 | F32: 1 | G32: 3 | H32: =ROUND(IF(OR(總表!$G32="",總表!$D32=""),"0",(總表!$G32/總表!$D32)),2) -> 3
A33: 巴雷諾斯自治領 | B33: 奧爾比亞村莊 | C33: 奧爾比亞2-3號 | D33: 1 | E33: 倉庫 | F33: 1 | G33: 3 | H33: =ROUND(IF(OR(總表!$G33="",總表!$D33=""),"0",(總表!$G33/總表!$D33)),2) -> 3
A34: 巴雷諾斯自治領 | B34: 奧爾比亞村莊 | C34: 奧爾比亞3-1號 | D34: 1 | E34: 倉庫 | F34: 1 | G34: 3 | H34: =ROUND(IF(OR(總表!$G34="",總表!$D34=""),"0",(總表!$G34/總表!$D34)),2) -> 3
A35: 巴雷諾斯自治領 | B35: 奧爾比亞村莊 | C35: 奧爾比亞3-2號 | D35: 1 | E35: 倉庫 | F35: 1 | G35: 3 | H35: =ROUND(IF(OR(總表!$G35="",總表!$D35=""),"0",(總表!$G35/總表!$D35)),2) -> 3
A36: 巴雷諾斯自治領 | B36: 奧爾比亞村莊 | C36: 奧爾比亞5-1號 | D36: 1 | E36: 倉庫 | F36: 1 | G36: 3 | H36: =ROUND(IF(OR(總表!$G36="",總表!$D36=""),"0",(總表!$G36/總表!$D36)),2) -> 3
A37: 巴雷諾斯自治領 | B37: 奧爾比亞村莊 | C37: 奧爾比亞6-1號 | D37: 1 | E37: 倉庫 | F37: 1 | G37: 3 | H37: =ROUND(IF(OR(總表!$G37="",總表!$D37=""),"0",(總表!$G37/總表!$D37)),2) -> 3
A38: 巴雷諾斯自治領 | B38: 奧爾比亞村莊 | C38: 奧爾比亞7-1號 | D38: 1 | E38: 倉庫 | F38: 1 | G38: 3 | H38: =ROUND(IF(OR(總表!$G38="",總表!$D38=""),"0",(總表!$G38/總表!$D38)),2) -> 3
... A83: 巴雷諾斯自治領 | B83: 伊利亞島 | C83: 伊利亞島6-2號 | D83: 2 | E83: 宿舍 | F83: 1 | G83: 1 | H83: =ROUND(IF(OR(總表!$G83="",總表!$D83=""),"0",(總表!$G83/總表!$D83)),2) -> 0.5
A84: 巴雷諾斯自治領 | B84: 貝爾利亞村莊 | C84: 貝爾利亞4號 | D84: 3 | E84: 武器鍛造工坊 | F84: 1 | H84: =ROUND(IF(OR(總表!$G84="",總表!$D84=""),"0",(總表!$G84/總表!$D84)),2) -> 0
A85: 巴雷諾斯自治領 | B85: 貝爾利亞村莊 | C85: 貝爾利亞4號 | D85: 3 | E85: 盔甲鍛造工坊 | F85: 1 | H85: =ROUND(IF(OR(總表!$G85="",總表!$D85=""),"0",(總表!$G85/總表!$D85)),2) -> 0
A86: 巴雷諾斯自治領 | B86: 貝爾利亞村莊 | C86: 貝爾利亞4號 | D86: 3 | E86: 安全性資產管理所 | F86: 1 | H86: =ROUND(IF(OR(總表!$G86="",總表!$D86=""),"0",(總表!$G86/總表!$D86)),2) -> 0
A87: 巴雷諾斯自治領 | B87: 貝爾利亞村莊 | C87: 貝爾利亞4號 | D87: 3 | E87: 居住地 | F87: 1 | H87: =ROUND(IF(OR(總表!$G87="",總表!$D87=""),"0",(總表!$G87/總表!$D87)),2) -> 0
A88: 巴雷諾斯自治領 | B88: 貝爾利亞村莊 | C88: 貝爾利亞2-2號 | D88: 2 | E88: 木工藝工坊 | F88: 1 | H88: =ROUND(IF(OR(總表!$G88="",總表!$D88=""),"0",(總表!$G88/總表!$D88)),2) -> 0
...
